<?xml version="1.0" ?>
<!-- =================================================================================== -->
<!-- |    This document was autogenerated by xacro from 2_wheel_config.urdf.xacro      | -->
<!-- |    EDITING THIS FILE BY HAND IS NOT RECOMMENDED                                 | -->
<!-- =================================================================================== -->
<!--
Copyright (c) 2021
KELO Robotics GmbH

Author:
Sushant Chavan


This software is published under a dual-license: GNU Lesser General Public
License LGPL 2.1 and BSD license. The dual-license implies that users of this
code may choose which terms they prefer.

Redistribution and use in source and binary forms, with or without
modification, are permitted provided that the following conditions are met:

* Redistributions of source code must retain the above copyright
notice, this list of conditions and the following disclaimer.
* Redistributions in binary form must reproduce the above copyright
notice, this list of conditions and the following disclaimer in the
documentation and/or other materials provided with the distribution.
* Neither the name of Locomotec nor the names of its
contributors may be used to endorse or promote products derived from
this software without specific prior written permission.

This program is free software: you can redistribute it and/or modify
it under the terms of the GNU Lesser General Public License LGPL as
published by the Free Software Foundation, either version 2.1 of the
License, or (at your option) any later version or the BSD license.

This program is distributed in the hope that it will be useful,
but WITHOUT ANY WARRANTY; without even the implied warranty of
MERCHANTABILITY or FITNESS FOR A PARTICULAR PURPOSE. See the
GNU Lesser General Public License LGPL and the BSD license for more details.

You should have received a copy of the GNU Lesser General Public
License LGPL and BSD license along with this program.
-->
<robot name="2_wheel_config">
  <link name="base_link"/>
  <joint name="robile_1_joint" type="fixed">
    <origin rpy="0.0 0.0 0.0" xyz="0.233 0.1165 0.05"/>
    <parent link="base_link"/>
    <child link="robile_1_link"/>
  </joint>
  <link name="robile_1_link">
    <!-- Aluminium casing of the robile -->
    <visual>
      <origin rpy="0 0 0" xyz="0 0 0"/>
      <geometry>
        <mesh filename="file:///home/sunesh/ros2_ws/install/robile_description/share/robile_description/meshes/robile_brick_housing/wheeled_brick_housing.dae" scale="1 1 1"/>
      </geometry>
    </visual>
    <!-- robile lid -->
    <visual>
      <origin rpy="0 0 0" xyz="0 0 0"/>
      <geometry>
        <mesh filename="file:///home/sunesh/ros2_ws/install/robile_description/share/robile_description/meshes/robile_brick_housing/lid.dae" scale="1 1 1"/>
      </geometry>
    </visual>
    <!-- robile lid cover (color passed as a parameter) -->
    <visual>
      <origin rpy="0 0 0" xyz="0 0 0"/>
      <geometry>
        <mesh filename="file:///home/sunesh/ros2_ws/install/robile_description/share/robile_description/meshes/robile_brick_housing/lid_cover_blue.dae" scale="1 1 1"/>
      </geometry>
    </visual>
    <!-- Collision box for brick housing -->
    <collision>
      <origin rpy="0 0 0" xyz="0.0005 0.0001 0.119"/>
      <geometry>
        <box size="0.233 0.233 0.239"/>
      </geometry>
    </collision>
    <inertial>
      <origin rpy="0 0 0" xyz="0.0005 0.0001 0.119"/>
      <mass value="5.0"/>
      <inertia ixx="0.04642083333333334" ixy="0.0" ixz="0.0" iyy="0.04642083333333334" iyz="0.0" izz="0.04524083333333334"/>
    </inertial>
  </link>
  <joint name="robile_1_caster_wheel_pivot_caster_joint" type="continuous">
    <origin rpy="0 0 0.0" xyz="0 0 0"/>
    <axis xyz="0 0 1"/>
    <parent link="robile_1_link"/>
    <child link="robile_1_caster_wheel_pivot_link"/>
  </joint>
  <transmission name="robile_1_caster_wheel_pivot_transmission">
    <type>transmission_interface/SimpleTransmission</type>
    <joint name="robile_1_caster_wheel_pivot_caster_joint">
      <hardwareInterface>hardware_interface/EffortJointInterface</hardwareInterface>
    </joint>
    <actuator name="robile_1_caster_wheel_pivot_motor">
      <hardwareInterface>hardware_interface/EffortJointInterface</hardwareInterface>
      <mechanicalReduction>1</mechanicalReduction>
    </actuator>
  </transmission>
  <link name="robile_1_caster_wheel_pivot_link">
    <visual>
      <origin rpy="0 0 0" xyz="0 0 0"/>
      <geometry>
        <mesh filename="file:///home/sunesh/ros2_ws/install/robile_description/share/robile_description/meshes/passive_caster_wheel/pivot.dae" scale="1 1 1"/>
      </geometry>
    </visual>
    <inertial>
      <origin rpy="0 0 0" xyz="0 0 0.045"/>
      <mass value="0.5"/>
      <inertia ixx="0.0006988004166666667" ixy="0.0" ixz="0.0" iyy="0.0005872604166666666" iyz="0.0" izz="0.00061854"/>
    </inertial>
  </link>
  <!-- CASTER OFFSET -->
  <joint name="robile_1_caster_wheel_caster_offset_joint" type="fixed">
    <origin rpy="0 0 0" xyz="0.031557 -0.00007 0.0"/>
    <parent link="robile_1_caster_wheel_pivot_link"/>
    <child link="robile_1_caster_wheel_caster_offset_link"/>
  </joint>
  <link name="robile_1_caster_wheel_caster_offset_link">
    <inertial>
      <origin rpy="0 0 0" xyz="0 0 0"/>
      <mass value="0.1"/>
      <inertia ixx="1.6666666666666667e-06" ixy="0.0" ixz="0.0" iyy="1.6666666666666667e-06" iyz="0.0" izz="1.6666666666666667e-06"/>
    </inertial>
  </link>
  <joint name="robile_1_caster_wheel_wheel_joint" type="continuous">
    <origin rpy="0 0 0" xyz="0 0 0"/>
    <axis xyz="0 1 0"/>
    <parent link="robile_1_caster_wheel_caster_offset_link"/>
    <child link="robile_1_caster_wheel_wheel_link"/>
  </joint>
  <transmission name="robile_1_caster_wheel_wheel_transmission">
    <type>transmission_interface/SimpleTransmission</type>
    <joint name="robile_1_caster_wheel_wheel_joint">
      <hardwareInterface>hardware_interface/EffortJointInterface</hardwareInterface>
    </joint>
    <actuator name="robile_1_caster_wheel_wheel_motor">
      <hardwareInterface>hardware_interface/EffortJointInterface</hardwareInterface>
      <mechanicalReduction>1</mechanicalReduction>
    </actuator>
  </transmission>
  <link name="robile_1_caster_wheel_wheel_link">
    <visual>
      <origin rpy="0 0 0" xyz="-0.031557 0.00007 0.0"/>
      <geometry>
        <mesh filename="file:///home/sunesh/ros2_ws/install/robile_description/share/robile_description/meshes/passive_caster_wheel/wheel.dae" scale="1 1 1"/>
      </geometry>
    </visual>
    <collision>
      <origin rpy="1.570796327 0 0" xyz="0 0 0"/>
      <geometry>
        <cylinder length="0.03" radius="0.05"/>
      </geometry>
    </collision>
    <inertial>
      <origin rpy="1.570796327 0 0" xyz="0 0 0"/>
      <mass value="0.5"/>
      <inertia ixx="0.00035000000000000005" ixy="0.0" ixz="0.0" iyy="0.00035000000000000005" iyz="0.0" izz="0.0006250000000000001"/>
    </inertial>
  </link>
  <joint name="robile_2_joint" type="fixed">
    <origin rpy="0.0 0.0 0.0" xyz="0.233 -0.1165 0.05"/>
    <parent link="base_link"/>
    <child link="robile_2_link"/>
  </joint>
  <link name="robile_2_link">
    <!-- Aluminium casing of the robile -->
    <visual>
      <origin rpy="0 0 0" xyz="0 0 0"/>
      <geometry>
        <mesh filename="file:///home/sunesh/ros2_ws/install/robile_description/share/robile_description/meshes/robile_brick_housing/wheeled_brick_housing.dae" scale="1 1 1"/>
      </geometry>
    </visual>
    <!-- robile lid -->
    <visual>
      <origin rpy="0 0 0" xyz="0 0 0"/>
      <geometry>
        <mesh filename="file:///home/sunesh/ros2_ws/install/robile_description/share/robile_description/meshes/robile_brick_housing/lid.dae" scale="1 1 1"/>
      </geometry>
    </visual>
    <!-- robile lid cover (color passed as a parameter) -->
    <visual>
      <origin rpy="0 0 0" xyz="0 0 0"/>
      <geometry>
        <mesh filename="file:///home/sunesh/ros2_ws/install/robile_description/share/robile_description/meshes/robile_brick_housing/lid_cover_blue.dae" scale="1 1 1"/>
      </geometry>
    </visual>
    <!-- Collision box for brick housing -->
    <collision>
      <origin rpy="0 0 0" xyz="0.0005 0.0001 0.119"/>
      <geometry>
        <box size="0.233 0.233 0.239"/>
      </geometry>
    </collision>
    <inertial>
      <origin rpy="0 0 0" xyz="0.0005 0.0001 0.119"/>
      <mass value="5.0"/>
      <inertia ixx="0.04642083333333334" ixy="0.0" ixz="0.0" iyy="0.04642083333333334" iyz="0.0" izz="0.04524083333333334"/>
    </inertial>
  </link>
  <joint name="robile_2_caster_wheel_pivot_caster_joint" type="continuous">
    <origin rpy="0 0 0.0" xyz="0 0 0"/>
    <axis xyz="0 0 1"/>
    <parent link="robile_2_link"/>
    <child link="robile_2_caster_wheel_pivot_link"/>
  </joint>
  <transmission name="robile_2_caster_wheel_pivot_transmission">
    <type>transmission_interface/SimpleTransmission</type>
    <joint name="robile_2_caster_wheel_pivot_caster_joint">
      <hardwareInterface>hardware_interface/EffortJointInterface</hardwareInterface>
    </joint>
    <actuator name="robile_2_caster_wheel_pivot_motor">
      <hardwareInterface>hardware_interface/EffortJointInterface</hardwareInterface>
      <mechanicalReduction>1</mechanicalReduction>
    </actuator>
  </transmission>
  <link name="robile_2_caster_wheel_pivot_link">
    <visual>
      <origin rpy="0 0 0" xyz="0 0 0"/>
      <geometry>
        <mesh filename="file:///home/sunesh/ros2_ws/install/robile_description/share/robile_description/meshes/passive_caster_wheel/pivot.dae" scale="1 1 1"/>
      </geometry>
    </visual>
    <inertial>
      <origin rpy="0 0 0" xyz="0 0 0.045"/>
      <mass value="0.5"/>
      <inertia ixx="0.0006988004166666667" ixy="0.0" ixz="0.0" iyy="0.0005872604166666666" iyz="0.0" izz="0.00061854"/>
    </inertial>
  </link>
  <!-- CASTER OFFSET -->
  <joint name="robile_2_caster_wheel_caster_offset_joint" type="fixed">
    <origin rpy="0 0 0" xyz="0.031557 -0.00007 0.0"/>
    <parent link="robile_2_caster_wheel_pivot_link"/>
    <child link="robile_2_caster_wheel_caster_offset_link"/>
  </joint>
  <link name="robile_2_caster_wheel_caster_offset_link">
    <inertial>
      <origin rpy="0 0 0" xyz="0 0 0"/>
      <mass value="0.1"/>
      <inertia ixx="1.6666666666666667e-06" ixy="0.0" ixz="0.0" iyy="1.6666666666666667e-06" iyz="0.0" izz="1.6666666666666667e-06"/>
    </inertial>
  </link>
  <joint name="robile_2_caster_wheel_wheel_joint" type="continuous">
    <origin rpy="0 0 0" xyz="0 0 0"/>
    <axis xyz="0 1 0"/>
    <parent link="robile_2_caster_wheel_caster_offset_link"/>
    <child link="robile_2_caster_wheel_wheel_link"/>
  </joint>
  <transmission name="robile_2_caster_wheel_wheel_transmission">
    <type>transmission_interface/SimpleTransmission</type>
    <joint name="robile_2_caster_wheel_wheel_joint">
      <hardwareInterface>hardware_interface/EffortJointInterface</hardwareInterface>
    </joint>
    <actuator name="robile_2_caster_wheel_wheel_motor">
      <hardwareInterface>hardware_interface/EffortJointInterface</hardwareInterface>
      <mechanicalReduction>1</mechanicalReduction>
    </actuator>
  </transmission>
  <link name="robile_2_caster_wheel_wheel_link">
    <visual>
      <origin rpy="0 0 0" xyz="-0.031557 0.00007 0.0"/>
      <geometry>
        <mesh filename="file:///home/sunesh/ros2_ws/install/robile_description/share/robile_description/meshes/passive_caster_wheel/wheel.dae" scale="1 1 1"/>
      </geometry>
    </visual>
    <collision>
      <origin rpy="1.570796327 0 0" xyz="0 0 0"/>
      <geometry>
        <cylinder length="0.03" radius="0.05"/>
      </geometry>
    </collision>
    <inertial>
      <origin rpy="1.570796327 0 0" xyz="0 0 0"/>
      <mass value="0.5"/>
      <inertia ixx="0.00035000000000000005" ixy="0.0" ixz="0.0" iyy="0.00035000000000000005" iyz="0.0" izz="0.0006250000000000001"/>
    </inertial>
  </link>
  <joint name="robile_3_joint" type="fixed">
    <origin rpy="0.0 0.0 0.0" xyz="0.0 0.1165 0.05"/>
    <parent link="base_link"/>
    <child link="robile_3_link"/>
  </joint>
  <link name="robile_3_link">
    <!-- Aluminium casing of the robile -->
    <visual>
      <origin rpy="0 0 0" xyz="0 0 0"/>
      <geometry>
        <mesh filename="file:///home/sunesh/ros2_ws/install/robile_description/share/robile_description/meshes/robile_brick_housing/general_brick_housing.dae" scale="1 1 1"/>
      </geometry>
    </visual>
    <!-- robile lid -->
    <visual>
      <origin rpy="0 0 0" xyz="0 0 0"/>
      <geometry>
        <mesh filename="file:///home/sunesh/ros2_ws/install/robile_description/share/robile_description/meshes/robile_brick_housing/lid.dae" scale="1 1 1"/>
      </geometry>
    </visual>
    <!-- robile lid cover (color passed as a parameter) -->
    <visual>
      <origin rpy="0 0 0" xyz="0 0 0"/>
      <geometry>
        <mesh filename="file:///home/sunesh/ros2_ws/install/robile_description/share/robile_description/meshes/robile_brick_housing/lid_cover_yellow.dae" scale="1 1 1"/>
      </geometry>
    </visual>
    <!-- Collision box for brick housing -->
    <collision>
      <origin rpy="0 0 0" xyz="0.0005 0.0001 0.119"/>
      <geometry>
        <box size="0.233 0.233 0.239"/>
      </geometry>
    </collision>
    <inertial>
      <origin rpy="0 0 0" xyz="0.0005 0.0001 0.119"/>
      <mass value="5.0"/>
      <inertia ixx="0.04642083333333334" ixy="0.0" ixz="0.0" iyy="0.04642083333333334" iyz="0.0" izz="0.04524083333333334"/>
    </inertial>
  </link>
  <joint name="robile_4_joint" type="fixed">
    <origin rpy="0.0 0.0 0.0" xyz="0.0 -0.1165 0.05"/>
    <parent link="base_link"/>
    <child link="robile_4_link"/>
  </joint>
  <link name="robile_4_link">
    <!-- Aluminium casing of the robile -->
    <visual>
      <origin rpy="0 0 0" xyz="0 0 0"/>
      <geometry>
        <mesh filename="file:///home/sunesh/ros2_ws/install/robile_description/share/robile_description/meshes/robile_brick_housing/general_brick_housing.dae" scale="1 1 1"/>
      </geometry>
    </visual>
    <!-- robile lid -->
    <visual>
      <origin rpy="0 0 0" xyz="0 0 0"/>
      <geometry>
        <mesh filename="file:///home/sunesh/ros2_ws/install/robile_description/share/robile_description/meshes/robile_brick_housing/lid.dae" scale="1 1 1"/>
      </geometry>
    </visual>
    <!-- robile lid cover (color passed as a parameter) -->
    <visual>
      <origin rpy="0 0 0" xyz="0 0 0"/>
      <geometry>
        <mesh filename="file:///home/sunesh/ros2_ws/install/robile_description/share/robile_description/meshes/robile_brick_housing/lid_cover_green.dae" scale="1 1 1"/>
      </geometry>
    </visual>
    <!-- Collision box for brick housing -->
    <collision>
      <origin rpy="0 0 0" xyz="0.0005 0.0001 0.119"/>
      <geometry>
        <box size="0.233 0.233 0.239"/>
      </geometry>
    </collision>
    <inertial>
      <origin rpy="0 0 0" xyz="0.0005 0.0001 0.119"/>
      <mass value="5.0"/>
      <inertia ixx="0.04642083333333334" ixy="0.0" ixz="0.0" iyy="0.04642083333333334" iyz="0.0" izz="0.04524083333333334"/>
    </inertial>
  </link>
  <joint name="robile_5_joint" type="fixed">
    <origin rpy="0.0 0.0 0.0" xyz="-0.233 0.1165 0.05"/>
    <parent link="base_link"/>
    <child link="robile_5_link"/>
  </joint>
  <link name="robile_5_link">
    <!-- Aluminium casing of the robile -->
    <visual>
      <origin rpy="0 0 0" xyz="0 0 0"/>
      <geometry>
        <mesh filename="file:///home/sunesh/ros2_ws/install/robile_description/share/robile_description/meshes/robile_brick_housing/wheeled_brick_housing.dae" scale="1 1 1"/>
      </geometry>
    </visual>
    <!-- robile lid -->
    <visual>
      <origin rpy="0 0 0" xyz="0 0 0"/>
      <geometry>
        <mesh filename="file:///home/sunesh/ros2_ws/install/robile_description/share/robile_description/meshes/robile_brick_housing/lid.dae" scale="1 1 1"/>
      </geometry>
    </visual>
    <!-- robile lid cover (color passed as a parameter) -->
    <visual>
      <origin rpy="0 0 0" xyz="0 0 0"/>
      <geometry>
        <mesh filename="file:///home/sunesh/ros2_ws/install/robile_description/share/robile_description/meshes/robile_brick_housing/lid_cover_red.dae" scale="1 1 1"/>
      </geometry>
    </visual>
    <!-- Collision box for brick housing -->
    <collision>
      <origin rpy="0 0 0" xyz="0.0005 0.0001 0.119"/>
      <geometry>
        <box size="0.233 0.233 0.239"/>
      </geometry>
    </collision>
    <inertial>
      <origin rpy="0 0 0" xyz="0.0005 0.0001 0.119"/>
      <mass value="5.0"/>
      <inertia ixx="0.04642083333333334" ixy="0.0" ixz="0.0" iyy="0.04642083333333334" iyz="0.0" izz="0.04524083333333334"/>
    </inertial>
  </link>
  <joint name="robile_5_drive_pivot_joint" type="continuous">
    <origin rpy="0 0 0.0" xyz="0 0 0"/>
    <axis xyz="0 0 1"/>
    <parent link="robile_5_link"/>
    <child link="robile_5_drive_pivot_link"/>
  </joint>
  <transmission name="robile_5_drive_pivot_transmission">
    <type>transmission_interface/SimpleTransmission</type>
    <joint name="robile_5_drive_pivot_joint">
      <hardwareInterface>hardware_interface/EffortJointInterface</hardwareInterface>
    </joint>
    <actuator name="robile_5_drive_pivot_motor">
      <hardwareInterface>hardware_interface/EffortJointInterface</hardwareInterface>
      <mechanicalReduction>1</mechanicalReduction>
    </actuator>
  </transmission>
  <link name="robile_5_drive_pivot_link">
    <visual>
      <origin rpy="0 0 0" xyz="0 0 0"/>
      <geometry>
        <mesh filename="file:///home/sunesh/ros2_ws/install/robile_description/share/robile_description/meshes/kelo_drive/kelo_drive_base.dae" scale="1 1 1"/>
      </geometry>
    </visual>
    <!--TODO: Set the correct collisions -->
    <collision>
      <origin rpy="0 0 0" xyz="0 0 0.07"/>
      <geometry>
        <box size="0.105 0.154 0.025"/>
      </geometry>
    </collision>
    <inertial>
      <origin rpy="0 0 0" xyz="0 0 0"/>
      <mass value="10.0"/>
      <inertia ixx="0.09048166666666668" ixy="0.0" ixz="0.0" iyy="0.09048166666666668" iyz="0.0" izz="0.09048166666666668"/>
    </inertial>
  </link>
  <joint name="robile_5_drive_left_hub_wheel_joint" type="continuous">
    <origin rpy="0 0 0.0" xyz="-0.01 0.039326 0.001514"/>
    <axis xyz="0 1 0"/>
    <parent link="robile_5_drive_pivot_link"/>
    <child link="robile_5_drive_left_hub_wheel_link"/>
  </joint>
  <transmission name="robile_5_drive_left_hub_wheel_transmission">
    <type>transmission_interface/SimpleTransmission</type>
    <joint name="robile_5_drive_left_hub_wheel_joint">
      <hardwareInterface>hardware_interface/EffortJointInterface</hardwareInterface>
    </joint>
    <actuator name="robile_5_drive_left_hub_wheel_motor">
      <hardwareInterface>hardware_interface/EffortJointInterface</hardwareInterface>
      <mechanicalReduction>1</mechanicalReduction>
    </actuator>
  </transmission>
  <link name="robile_5_drive_left_hub_wheel_link">
    <visual>
      <origin rpy="0 0 0" xyz="0 0 0"/>
      <geometry>
        <mesh filename="file:///home/sunesh/ros2_ws/install/robile_description/share/robile_description/meshes/kelo_drive/kelo_drive_wheel.dae" scale="1 1 1"/>
      </geometry>
    </visual>
    <collision>
      <origin rpy="1.570796327 0 0" xyz="0 0 0"/>
      <geometry>
        <cylinder length="0.035" radius="0.0515"/>
      </geometry>
    </collision>
    <inertial>
      <origin rpy="0 0 0" xyz="0 0 0"/>
      <mass value="10.0"/>
      <inertia ixx="0.09048166666666668" ixy="0.0" ixz="0.0" iyy="0.09048166666666668" iyz="0.0" izz="0.09048166666666668"/>
    </inertial>
  </link>
  <joint name="robile_5_drive_right_hub_wheel_joint" type="continuous">
    <origin rpy="0 0 0.0" xyz="-0.01 -0.039326 0.001514"/>
    <axis xyz="0 1 0"/>
    <parent link="robile_5_drive_pivot_link"/>
    <child link="robile_5_drive_right_hub_wheel_link"/>
  </joint>
  <transmission name="robile_5_drive_right_hub_wheel_transmission">
    <type>transmission_interface/SimpleTransmission</type>
    <joint name="robile_5_drive_right_hub_wheel_joint">
      <hardwareInterface>hardware_interface/EffortJointInterface</hardwareInterface>
    </joint>
    <actuator name="robile_5_drive_right_hub_wheel_motor">
      <hardwareInterface>hardware_interface/EffortJointInterface</hardwareInterface>
      <mechanicalReduction>1</mechanicalReduction>
    </actuator>
  </transmission>
  <link name="robile_5_drive_right_hub_wheel_link">
    <visual>
      <origin rpy="0 0 0" xyz="0 0 0"/>
      <geometry>
        <mesh filename="file:///home/sunesh/ros2_ws/install/robile_description/share/robile_description/meshes/kelo_drive/kelo_drive_wheel.dae" scale="1 1 1"/>
      </geometry>
    </visual>
    <collision>
      <origin rpy="1.570796327 0 0" xyz="0 0 0"/>
      <geometry>
        <cylinder length="0.035" radius="0.0515"/>
      </geometry>
    </collision>
    <inertial>
      <origin rpy="0 0 0" xyz="0 0 0"/>
      <mass value="10.0"/>
      <inertia ixx="0.09048166666666668" ixy="0.0" ixz="0.0" iyy="0.09048166666666668" iyz="0.0" izz="0.09048166666666668"/>
    </inertial>
  </link>
  <joint name="robile_6_joint" type="fixed">
    <origin rpy="0.0 0.0 0.0" xyz="-0.233 -0.1165 0.05"/>
    <parent link="base_link"/>
    <child link="robile_6_link"/>
  </joint>
  <link name="robile_6_link">
    <!-- Aluminium casing of the robile -->
    <visual>
      <origin rpy="0 0 0" xyz="0 0 0"/>
      <geometry>
        <mesh filename="file:///home/sunesh/ros2_ws/install/robile_description/share/robile_description/meshes/robile_brick_housing/wheeled_brick_housing.dae" scale="1 1 1"/>
      </geometry>
    </visual>
    <!-- robile lid -->
    <visual>
      <origin rpy="0 0 0" xyz="0 0 0"/>
      <geometry>
        <mesh filename="file:///home/sunesh/ros2_ws/install/robile_description/share/robile_description/meshes/robile_brick_housing/lid.dae" scale="1 1 1"/>
      </geometry>
    </visual>
    <!-- robile lid cover (color passed as a parameter) -->
    <visual>
      <origin rpy="0 0 0" xyz="0 0 0"/>
      <geometry>
        <mesh filename="file:///home/sunesh/ros2_ws/install/robile_description/share/robile_description/meshes/robile_brick_housing/lid_cover_red.dae" scale="1 1 1"/>
      </geometry>
    </visual>
    <!-- Collision box for brick housing -->
    <collision>
      <origin rpy="0 0 0" xyz="0.0005 0.0001 0.119"/>
      <geometry>
        <box size="0.233 0.233 0.239"/>
      </geometry>
    </collision>
    <inertial>
      <origin rpy="0 0 0" xyz="0.0005 0.0001 0.119"/>
      <mass value="5.0"/>
      <inertia ixx="0.04642083333333334" ixy="0.0" ixz="0.0" iyy="0.04642083333333334" iyz="0.0" izz="0.04524083333333334"/>
    </inertial>
  </link>
  <joint name="robile_6_drive_pivot_joint" type="continuous">
    <origin rpy="0 0 0.0" xyz="0 0 0"/>
    <axis xyz="0 0 1"/>
    <parent link="robile_6_link"/>
    <child link="robile_6_drive_pivot_link"/>
  </joint>
  <transmission name="robile_6_drive_pivot_transmission">
    <type>transmission_interface/SimpleTransmission</type>
    <joint name="robile_6_drive_pivot_joint">
      <hardwareInterface>hardware_interface/EffortJointInterface</hardwareInterface>
    </joint>
    <actuator name="robile_6_drive_pivot_motor">
      <hardwareInterface>hardware_interface/EffortJointInterface</hardwareInterface>
      <mechanicalReduction>1</mechanicalReduction>
    </actuator>
  </transmission>
  <link name="robile_6_drive_pivot_link">
    <visual>
      <origin rpy="0 0 0" xyz="0 0 0"/>
      <geometry>
        <mesh filename="file:///home/sunesh/ros2_ws/install/robile_description/share/robile_description/meshes/kelo_drive/kelo_drive_base.dae" scale="1 1 1"/>
      </geometry>
    </visual>
    <!--TODO: Set the correct collisions -->
    <collision>
      <origin rpy="0 0 0" xyz="0 0 0.07"/>
      <geometry>
        <box size="0.105 0.154 0.025"/>
      </geometry>
    </collision>
    <inertial>
      <origin rpy="0 0 0" xyz="0 0 0"/>
      <mass value="10.0"/>
      <inertia ixx="0.09048166666666668" ixy="0.0" ixz="0.0" iyy="0.09048166666666668" iyz="0.0" izz="0.09048166666666668"/>
    </inertial>
  </link>
  <joint name="robile_6_drive_left_hub_wheel_joint" type="continuous">
    <origin rpy="0 0 0.0" xyz="-0.01 0.039326 0.001514"/>
    <axis xyz="0 1 0"/>
    <parent link="robile_6_drive_pivot_link"/>
    <child link="robile_6_drive_left_hub_wheel_link"/>
  </joint>
  <transmission name="robile_6_drive_left_hub_wheel_transmission">
    <type>transmission_interface/SimpleTransmission</type>
    <joint name="robile_6_drive_left_hub_wheel_joint">
      <hardwareInterface>hardware_interface/EffortJointInterface</hardwareInterface>
    </joint>
    <actuator name="robile_6_drive_left_hub_wheel_motor">
      <hardwareInterface>hardware_interface/EffortJointInterface</hardwareInterface>
      <mechanicalReduction>1</mechanicalReduction>
    </actuator>
  </transmission>
  <link name="robile_6_drive_left_hub_wheel_link">
    <visual>
      <origin rpy="0 0 0" xyz="0 0 0"/>
      <geometry>
        <mesh filename="file:///home/sunesh/ros2_ws/install/robile_description/share/robile_description/meshes/kelo_drive/kelo_drive_wheel.dae" scale="1 1 1"/>
      </geometry>
    </visual>
    <collision>
      <origin rpy="1.570796327 0 0" xyz="0 0 0"/>
      <geometry>
        <cylinder length="0.035" radius="0.0515"/>
      </geometry>
    </collision>
    <inertial>
      <origin rpy="0 0 0" xyz="0 0 0"/>
      <mass value="10.0"/>
      <inertia ixx="0.09048166666666668" ixy="0.0" ixz="0.0" iyy="0.09048166666666668" iyz="0.0" izz="0.09048166666666668"/>
    </inertial>
  </link>
  <joint name="robile_6_drive_right_hub_wheel_joint" type="continuous">
    <origin rpy="0 0 0.0" xyz="-0.01 -0.039326 0.001514"/>
    <axis xyz="0 1 0"/>
    <parent link="robile_6_drive_pivot_link"/>
    <child link="robile_6_drive_right_hub_wheel_link"/>
  </joint>
  <transmission name="robile_6_drive_right_hub_wheel_transmission">
    <type>transmission_interface/SimpleTransmission</type>
    <joint name="robile_6_drive_right_hub_wheel_joint">
      <hardwareInterface>hardware_interface/EffortJointInterface</hardwareInterface>
    </joint>
    <actuator name="robile_6_drive_right_hub_wheel_motor">
      <hardwareInterface>hardware_interface/EffortJointInterface</hardwareInterface>
      <mechanicalReduction>1</mechanicalReduction>
    </actuator>
  </transmission>
  <link name="robile_6_drive_right_hub_wheel_link">
    <visual>
      <origin rpy="0 0 0" xyz="0 0 0"/>
      <geometry>
        <mesh filename="file:///home/sunesh/ros2_ws/install/robile_description/share/robile_description/meshes/kelo_drive/kelo_drive_wheel.dae" scale="1 1 1"/>
      </geometry>
    </visual>
    <collision>
      <origin rpy="1.570796327 0 0" xyz="0 0 0"/>
      <geometry>
        <cylinder length="0.035" radius="0.0515"/>
      </geometry>
    </collision>
    <inertial>
      <origin rpy="0 0 0" xyz="0 0 0"/>
      <mass value="10.0"/>
      <inertia ixx="0.09048166666666668" ixy="0.0" ixz="0.0" iyy="0.09048166666666668" iyz="0.0" izz="0.09048166666666668"/>
    </inertial>
  </link>
</robot>
